<?xml version="1.0" encoding="utf-8"?>
<!-- =================================================================================== -->
<!-- |    This document was autogenerated by xacro from mue.urdf.xacro                 | -->
<!-- |    EDITING THIS FILE BY HAND IS NOT RECOMMENDED                                 | -->
<!-- =================================================================================== -->
<robot name="mue" xmlns:controller="http://playerstage.sourceforge.net/gazebo/xmlschema/#controller" xmlns:interface="http://playerstage.sourceforge.net/gazebo/xmlschema/#interface" xmlns:sensor="http://playerstage.sourceforge.net/gazebo/xmlschema/#sensor">
  <!--Include all needed urdf files-->
  <!-- old -->
  <!-- "prefix joint_limited
    shoulder_pan_lower_limit:=${-pi}    shoulder_pan_upper_limit:=${pi}
    shoulder_lift_lower_limit:=${-pi}    shoulder_lift_upper_limit:=${pi}
    elbow_joint_lower_limit:=${-pi}    elbow_joint_upper_limit:=${pi}
    wrist_1_lower_limit:=${-pi}    wrist_1_upper_limit:=${pi}
    wrist_2_lower_limit:=${-pi}    wrist_2_upper_limit:=${pi}
    wrist_3_lower_limit:=${-pi}    wrist_3_upper_limit:=${pi}
    transmission_hw_interface:=hardware_interface/PositionJointInterface
    safety_limits:=false safety_pos_margin:=0.15
    safety_k_position:=20" -->
  <!--property name="shoulder_height" value="0.089159" /-->
  <!--property name="shoulder_offset" value="0.13585" /-->
  <!-- shoulder_offset - elbow_offset + wrist_1_length = 0.10915 -->
  <!--property name="upper_arm_length" value="0.42500" /-->
  <!--property name="elbow_offset" value="0.1197" /-->
  <!-- CAD measured -->
  <!--property name="forearm_length" value="0.39225" /-->
  <!--property name="wrist_1_length" value="0.093" /-->
  <!-- CAD measured -->
  <!--property name="wrist_2_length" value="0.09465" /-->
  <!-- In CAD this distance is 0.930, but in the spec it is 0.09465 -->
  <!--property name="wrist_3_length" value="0.0823" /-->
  <!-- manually measured -->
  <link name="base_link_ur5e">
    <visual>
      <geometry>
        <mesh filename="package://mue_description/meshes/ur5e/visual/base.dae"/>
      </geometry>
      <material name="LightGrey">
        <color rgba="0.7 0.7 0.7 1.0"/>
      </material>
    </visual>
    <collision>
      <geometry>
        <mesh filename="package://mue_description/meshes/ur5e/collision/base.stl"/>
      </geometry>
    </collision>
    <inertial>
      <mass value="4.0"/>
      <origin rpy="0 0 0" xyz="0.0 0.0 0.0"/>
      <inertia ixx="0.00443333156" ixy="0.0" ixz="0.0" iyy="0.00443333156" iyz="0.0" izz="0.0072"/>
    </inertial>
  </link>
  <joint name="shoulder_pan_joint" type="revolute">
    <parent link="base_link_ur5e"/>
    <child link="shoulder_link"/>
    <origin rpy="0.0 0.0 0.0" xyz="0.0 0.0 0.1625"/>
    <axis xyz="0 0 1"/>
    <limit effort="150.0" lower="-6.28318530718" upper="6.28318530718" velocity="3.14"/>
    <dynamics damping="0.0" friction="0.0"/>
  </joint>
  <link name="shoulder_link">
    <visual>
      <geometry>
        <mesh filename="package://mue_description/meshes/ur5e/visual/shoulder.dae"/>
      </geometry>
      <material name="LightGrey">
        <color rgba="0.7 0.7 0.7 1.0"/>
      </material>
    </visual>
    <collision>
      <geometry>
        <mesh filename="package://mue_description/meshes/ur5e/collision/shoulder.stl"/>
      </geometry>
    </collision>
    <inertial>
      <mass value="3.7"/>
      <origin rpy="0 0 0" xyz="0.0 0.0 0.0"/>
      <inertia ixx="0.010267495893" ixy="0.0" ixz="0.0" iyy="0.010267495893" iyz="0.0" izz="0.00666"/>
    </inertial>
  </link>
  <joint name="shoulder_lift_joint" type="revolute">
    <parent link="shoulder_link"/>
    <child link="upper_arm_link"/>
    <origin rpy="0.0 1.57079632679 0.0" xyz="0.0 0.138 0.0"/>
    <axis xyz="0 1 0"/>
    <limit effort="150.0" lower="-6.28318530718" upper="6.28318530718" velocity="3.14"/>
    <dynamics damping="0.0" friction="0.0"/>
  </joint>
  <link name="upper_arm_link">
    <visual>
      <geometry>
        <mesh filename="package://mue_description/meshes/ur5e/visual/upperarm.dae"/>
      </geometry>
      <material name="LightGrey">
        <color rgba="0.7 0.7 0.7 1.0"/>
      </material>
    </visual>
    <collision>
      <geometry>
        <mesh filename="package://mue_description/meshes/ur5e/collision/upperarm.stl"/>
      </geometry>
    </collision>
    <inertial>
      <mass value="8.393"/>
      <origin rpy="0 0 0" xyz="0.0 0.0 0.2125"/>
      <inertia ixx="0.133885781862" ixy="0.0" ixz="0.0" iyy="0.133885781862" iyz="0.0" izz="0.0151074"/>
    </inertial>
  </link>
  <joint name="elbow_joint" type="revolute">
    <parent link="upper_arm_link"/>
    <child link="forearm_link"/>
    <origin rpy="0.0 0.0 0.0" xyz="0.0 -0.131 0.425"/>
    <axis xyz="0 1 0"/>
    <limit effort="150.0" lower="-3.14159265359" upper="3.14159265359" velocity="3.14"/>
    <dynamics damping="0.0" friction="0.0"/>
  </joint>
  <link name="forearm_link">
    <visual>
      <geometry>
        <mesh filename="package://mue_description/meshes/ur5e/visual/forearm.dae"/>
      </geometry>
      <material name="LightGrey">
        <color rgba="0.7 0.7 0.7 1.0"/>
      </material>
    </visual>
    <collision>
      <geometry>
        <mesh filename="package://mue_description/meshes/ur5e/collision/forearm.stl"/>
      </geometry>
    </collision>
    <inertial>
      <mass value="2.275"/>
      <origin rpy="0 0 0" xyz="0.0 0.0 0.196"/>
      <inertia ixx="0.0311796208615" ixy="0.0" ixz="0.0" iyy="0.0311796208615" iyz="0.0" izz="0.004095"/>
    </inertial>
  </link>
  <joint name="wrist_1_joint" type="revolute">
    <parent link="forearm_link"/>
    <child link="wrist_1_link"/>
    <origin rpy="0.0 1.57079632679 0.0" xyz="0.0 0.0 0.392"/>
    <axis xyz="0 1 0"/>
    <limit effort="28.0" lower="-6.28318530718" upper="6.28318530718" velocity="6.28"/>
    <dynamics damping="0.0" friction="0.0"/>
  </joint>
  <link name="wrist_1_link">
    <visual>
      <geometry>
        <mesh filename="package://mue_description/meshes/ur5e/visual/wrist1.dae"/>
      </geometry>
      <material name="LightGrey">
        <color rgba="0.7 0.7 0.7 1.0"/>
      </material>
    </visual>
    <collision>
      <geometry>
        <mesh filename="package://mue_description/meshes/ur5e/collision/wrist1.stl"/>
      </geometry>
    </collision>
    <inertial>
      <mass value="1.219"/>
      <origin rpy="0 0 0" xyz="0.0 0.1263 0.0"/>
      <inertia ixx="0.00255989897604" ixy="0.0" ixz="0.0" iyy="0.00255989897604" iyz="0.0" izz="0.0021942"/>
    </inertial>
  </link>
  <joint name="wrist_2_joint" type="revolute">
    <parent link="wrist_1_link"/>
    <child link="wrist_2_link"/>
    <origin rpy="0.0 0.0 0.0" xyz="0.0 0.1263 0.0"/>
    <axis xyz="0 0 1"/>
    <limit effort="28.0" lower="-6.28318530718" upper="6.28318530718" velocity="6.28"/>
    <dynamics damping="0.0" friction="0.0"/>
  </joint>
  <link name="wrist_2_link">
    <visual>
      <geometry>
        <mesh filename="package://mue_description/meshes/ur5e/visual/wrist2.dae"/>
      </geometry>
      <material name="LightGrey">
        <color rgba="0.7 0.7 0.7 1.0"/>
      </material>
    </visual>
    <collision>
      <geometry>
        <mesh filename="package://mue_description/meshes/ur5e/collision/wrist2.stl"/>
      </geometry>
    </collision>
    <inertial>
      <mass value="1.219"/>
      <origin rpy="0 0 0" xyz="0.0 0.0 0.0997"/>
      <inertia ixx="0.00255989897604" ixy="0.0" ixz="0.0" iyy="0.00255989897604" iyz="0.0" izz="0.0021942"/>
    </inertial>
  </link>
  <joint name="wrist_3_joint" type="revolute">
    <parent link="wrist_2_link"/>
    <child link="wrist_3_link"/>
    <origin rpy="0.0 0.0 0.0" xyz="0.0 0.0 0.0997"/>
    <axis xyz="0 1 0"/>
    <limit effort="28.0" lower="-6.28318530718" upper="6.28318530718" velocity="6.28"/>
    <dynamics damping="0.0" friction="0.0"/>
  </joint>
  <link name="wrist_3_link">
    <visual>
      <geometry>
        <mesh filename="package://mue_description/meshes/ur5e/visual/wrist3.dae"/>
      </geometry>
      <material name="LightGrey">
        <color rgba="0.7 0.7 0.7 1.0"/>
      </material>
    </visual>
    <collision>
      <geometry>
        <mesh filename="package://mue_description/meshes/ur5e/collision/wrist3.stl"/>
      </geometry>
    </collision>
    <inertial>
      <mass value="0.1879"/>
      <origin rpy="1.57079632679 0 0" xyz="0.0 0.0767 0.0"/>
      <inertia ixx="9.89041005217e-05" ixy="0.0" ixz="0.0" iyy="9.89041005217e-05" iyz="0.0" izz="0.0001321171875"/>
    </inertial>
  </link>
  <gazebo reference="wrist_3_link">
    <kp value="0.0"/>
    <!--stiffness coefficient-->
    <kd value="1.0"/>
    <!--dampening coefficient  old: 0.0-->
    <minDepth value="0.2"/>
    <maxVel value="0"/>
  </gazebo>
  <!-- ///////////////////////////////////////////////////////////////////////////////////////////////////////////////////// -->
  <!-- TODO: Attach a compliance tool link -->
  <!-- <joint name="${prefix}tool_joint" type="fixed">
      <parent link="${prefix}wrist_3_link"/>
      <child link="${prefix}tool_link"/>
      <origin xyz="0 ${wrist_3_length /2.0} 0" rpy="${-pi / 2.0} 0 ${pi / 2.0}"/>
    </joint>
    
    <link name="${prefix}tool_link">
	    <visual>
          <origin xyz="0 0 0" rpy="-0.01 0 0" />
          <geometry>
            <sphere radius="0.01"/>
          </geometry>
          <material name="white"/>
        </visual>
    </link>
 
   <gazebo reference="${prefix}tool_link">
      <kp value="0.0"/>
      <kd value="1.0"/>
      <minDepth value="0.2"/>
      <maxVel value="0"/>
    </gazebo> -->
  <!-- ///////////////////////////////////////////////////////////////////////////////////////////////////////////////////// -->
  <joint name="ee_fixed_joint" type="fixed">
    <parent link="wrist_3_link"/>
    <child link="ee_link"/>
    <origin rpy="0.0 0.0 1.57079632679" xyz="0.0 0.0996 0.0"/>
  </joint>
  <link name="ee_link">
    <visual>
      <origin rpy="0 0 0" xyz="0 0 0"/>
      <geometry>
        <sphere radius="0.01"/>
      </geometry>
      <material name="white"/>
    </visual>
    <collision>
      <geometry>
        <box size="0.01 0.01 0.01"/>
      </geometry>
    </collision>
  </link>
  <gazebo reference="ee_link">
    <kp value="0.0"/>
    <kd value="1.0"/>
    <minDepth value="0.2"/>
    <maxVel value="0"/>
  </gazebo>
  <!-- ///////////////////////////////////////////////////////////////////////////////////////////////////////////////////// -->
  <transmission name="shoulder_pan_trans">
    <type>transmission_interface/SimpleTransmission</type>
    <joint name="shoulder_pan_joint">
      <hardwareInterface>hardware_interface/PositionJointInterface</hardwareInterface>
      <hardwareInterface>hardware_interface/VelocityJointInterface</hardwareInterface>
    </joint>
    <actuator name="shoulder_pan_motor">
      <mechanicalReduction>1</mechanicalReduction>
    </actuator>
  </transmission>
  <transmission name="shoulder_lift_trans">
    <type>transmission_interface/SimpleTransmission</type>
    <joint name="shoulder_lift_joint">
      <hardwareInterface>hardware_interface/PositionJointInterface</hardwareInterface>
      <hardwareInterface>hardware_interface/VelocityJointInterface</hardwareInterface>
    </joint>
    <actuator name="shoulder_lift_motor">
      <mechanicalReduction>1</mechanicalReduction>
    </actuator>
  </transmission>
  <transmission name="elbow_trans">
    <type>transmission_interface/SimpleTransmission</type>
    <joint name="elbow_joint">
      <hardwareInterface>hardware_interface/PositionJointInterface</hardwareInterface>
      <hardwareInterface>hardware_interface/VelocityJointInterface</hardwareInterface>
    </joint>
    <actuator name="elbow_motor">
      <mechanicalReduction>1</mechanicalReduction>
    </actuator>
  </transmission>
  <transmission name="wrist_1_trans">
    <type>transmission_interface/SimpleTransmission</type>
    <joint name="wrist_1_joint">
      <hardwareInterface>hardware_interface/PositionJointInterface</hardwareInterface>
      <hardwareInterface>hardware_interface/VelocityJointInterface</hardwareInterface>
    </joint>
    <actuator name="wrist_1_motor">
      <mechanicalReduction>1</mechanicalReduction>
    </actuator>
  </transmission>
  <transmission name="wrist_2_trans">
    <type>transmission_interface/SimpleTransmission</type>
    <joint name="wrist_2_joint">
      <hardwareInterface>hardware_interface/PositionJointInterface</hardwareInterface>
      <hardwareInterface>hardware_interface/VelocityJointInterface</hardwareInterface>
    </joint>
    <actuator name="wrist_2_motor">
      <mechanicalReduction>1</mechanicalReduction>
    </actuator>
  </transmission>
  <transmission name="wrist_3_trans">
    <type>transmission_interface/SimpleTransmission</type>
    <joint name="wrist_3_joint">
      <hardwareInterface>hardware_interface/PositionJointInterface</hardwareInterface>
      <hardwareInterface>hardware_interface/VelocityJointInterface</hardwareInterface>
    </joint>
    <actuator name="wrist_3_motor">
      <mechanicalReduction>1</mechanicalReduction>
    </actuator>
  </transmission>
  <gazebo reference="shoulder_link">
    <selfCollide>true</selfCollide>
  </gazebo>
  <gazebo reference="upper_arm_link">
    <selfCollide>true</selfCollide>
  </gazebo>
  <gazebo reference="forearm_link">
    <selfCollide>true</selfCollide>
  </gazebo>
  <gazebo reference="wrist_1_link">
    <selfCollide>true</selfCollide>
  </gazebo>
  <gazebo reference="wrist_3_link">
    <selfCollide>true</selfCollide>
  </gazebo>
  <gazebo reference="wrist_2_link">
    <selfCollide>true</selfCollide>
  </gazebo>
  <gazebo reference="ee_link">
    <selfCollide>true</selfCollide>
  </gazebo>
  <!-- ROS base_link to UR 'Base' Coordinates transform -->
  <!-- <link name="${prefix}base"/>
    <joint name="${prefix}base_link_ur5e-base_fixed_joint" type="fixed"> -->
  <!-- NOTE: this rotation is only needed as long as base_link itself is
                 not corrected wrt the real robot (ie: rotated over 180
                 degrees)
      -->
  <!-- <origin xyz="0 0 0" rpy="0 0 ${-pi}"/>
      <parent link="${prefix}base_link_ur5e"/>
      <child link="${prefix}base"/>
    </joint> -->
  <!-- Frame coincident with all-zeros TCP on UR controller -->
  <!-- <link name="${prefix}tool0"/>
    <joint name="${prefix}wrist_3_link-tool0_fixed_joint" type="fixed">
      <origin xyz="0 ${wrist_3_length} 0" rpy="${pi/-2.0} 0 0"/>
      <parent link="${prefix}wrist_3_link"/>
      <child link="${prefix}tool0"/>
    </joint> -->
  <!--As MoveIt! seems to have difficulties with finding plans 
    for the UR with full joint limits [-2pi, 2pi], 
    there is a joint_limited version using joint limits restricted to [-pi,pi]. 
    In order to use this joint limited version set joint_limited="true"-->
  <!-- Start to xacro urdf -->
  <link name="base_footprint"/>
  <joint name="base_joint" type="fixed">
    <parent link="base_footprint"/>
    <child link="base_link"/>
    <origin rpy="0 0 0" xyz="0 0 0"/>
  </joint>
  <link name="base_link">
    <inertial>
      <mass value="20"/>
      <origin rpy="0 0 0" xyz="0.037646 0 0.20"/>
      <inertia ixx="0.7106663824" ixy="0.0" ixz="0.0" iyy="1.4999994" iyz="0.0" izz="1.9106659024"/>
    </inertial>
    <visual>
      <origin rpy="0 0 3.14159265359" xyz="0.025 -0.46174 0.261"/>
      <geometry>
        <mesh filename="package://lxfr_description/meshes/base_link.STL"/>
      </geometry>
      <material name="">
        <color rgba="0.792156862745098 0.819607843137255 0.933333333333333 1"/>
      </material>
    </visual>
    <collision>
      <origin rpy="0 0 0" xyz="0.037646 0 0"/>
      <geometry>
        <mesh filename="package://lxfr_description/meshes/lxfr_base.stl"/>
      </geometry>
      <friction>
        <ode>
          <mu>2</mu>
          <mu2>2</mu2>
        </ode>
      </friction>
    </collision>
  </link>
  <gazebo reference="base_link">
    <material>Gazebo/LightGrey</material>
  </gazebo>
  <!-- IMU -->
  <joint name="base_link_to_imu_joint" type="fixed">
    <parent link="base_link"/>
    <child link="imu_link"/>
    <origin rpy="0 0 0" xyz="0.0 0.0 0.25"/>
  </joint>
  <link name="imu_link"/>
  <gazebo reference="imu_link">
    <gravity>true</gravity>
    <sensor name="imu_sensor" type="imu">
      <always_on>true</always_on>
      <update_rate>100</update_rate>
      <!-- this is not the publish rate -->
      <visualize>true</visualize>
      <topic>__default_topic__</topic>
      <plugin filename="libgazebo_ros_imu_sensor.so" name="imu_plugin">
        <topicName>imu_data</topicName>
        <bodyName>imu_link</bodyName>
        <updateRateHZ>50.0</updateRateHZ>
        <!-- this is the publish rate -->
        <gaussianNoise>2.89e-08</gaussianNoise>
        <xyzOffset>0 0 0</xyzOffset>
        <rpyOffset>0 0 0</rpyOffset>
        <frameName>imu_frame</frameName>
      </plugin>
      <pose>0 0 0 0 0 0</pose>
    </sensor>
  </gazebo>
  <!-- Create an alias for imu_link. This is necessary because the real 
         TF has imu_link, but the imu_data topic is published in the imu_frame
         frame. -->
  <joint name="imu_link_to_imu_frame_joint" type="fixed">
    <parent link="imu_link"/>
    <child link="imu_frame"/>
    <origin rpy="0 0 0" xyz="0 0 0"/>
  </joint>
  <link name="imu_frame"/>
  <!-- Laser scanners -->
  <joint name="base_link_to_front_laser_joint" type="fixed">
    <parent link="base_link"/>
    <child link="front_laser_link"/>
    <!-- <origin xyz="0.4288 0.2358 0.1914" rpy="0.0 0.0 ${0.25 * pi}" />   -->
    <origin rpy="0.0 0.0 0.785398163397" xyz="0.45 0.25 0.1914"/>
  </joint>
  <link name="front_laser_link">
    <inertial>
      <mass value="2.0"/>
      <origin xyz="0 0 0"/>
      <inertia ixx="0.00970832945" ixy="0.0" ixz="0.0" iyy="0.0097601627626" iyz="0.0" izz="0.0080601634426"/>
    </inertial>
  </link>
  <gazebo reference="front_laser_link">
    <!-- <material value="Gazebo/Yellow" /> -->
    <material value="Gazebo/FlatBlack"/>
    <sensor name="front_laser_link" type="gpu_ray">
      <pose>0 0 0 0 0 0</pose>
      <visualize>false</visualize>
      <update_rate>12.5</update_rate>
      <ray>
        <scan>
          <horizontal>
            <samples>541</samples>
            <resolution>1</resolution>
            <!-- has to be 1; actual resolution will be computed from number of samples + min_angle/max_angle -->
            <min_angle>-2.35619449615</min_angle>
            <max_angle>2.35619449615</max_angle>
          </horizontal>
        </scan>
        <range>
          <min>0.05</min>
          <max>29.0</max>
          <resolution>0.01</resolution>
        </range>
        <noise>
          <type>gaussian</type>
          <!-- Noise parameters based on published spec for S300 achieving
                 "+-29mm" accuracy at range < 3m (~0.01 of the range) at
                 1 sigma. -->
          <mean>0.0</mean>
          <stddev>0.01</stddev>
        </noise>
      </ray>
      <plugin filename="libgazebo_ros_gpu_laser.so" name="gazebo_ros_front_laser_link_controller">
        <!-- no tf_prefix, plugin always uses a tf_prefix (if none is set it uses robotNamespace) -->
        <frameName>/front_laser_link</frameName>
        <topicName>f_scan</topicName>
      </plugin>
    </sensor>
  </gazebo>
  <joint name="base_link_to_back_laser_joint" type="fixed">
    <parent link="base_link"/>
    <child link="back_laser_link"/>
    <!-- <origin xyz="-0.3548 -0.2352 0.1914" rpy="0.0 0.0 ${-0.75 * pi}" /> -->
    <origin rpy="0.0 0.0 -2.35619449019" xyz="-0.45 -0.25 0.1914"/>
  </joint>
  <link name="back_laser_link">
    <inertial>
      <mass value="2.0"/>
      <origin xyz="0 0 0"/>
      <inertia ixx="0.00970832945" ixy="0.0" ixz="0.0" iyy="0.0097601627626" iyz="0.0" izz="0.0080601634426"/>
    </inertial>
  </link>
  <gazebo reference="back_laser_link">
    <!-- <material value="Gazebo/Yellow" /> -->
    <material value="Gazebo/FlatBlack"/>
    <sensor name="back_laser_link" type="gpu_ray">
      <pose>0 0 0 0 0 0</pose>
      <visualize>false</visualize>
      <update_rate>12.5</update_rate>
      <ray>
        <scan>
          <horizontal>
            <samples>541</samples>
            <resolution>1</resolution>
            <!-- has to be 1; actual resolution will be computed from number of samples + min_angle/max_angle -->
            <min_angle>-2.35619449615</min_angle>
            <max_angle>2.35619449615</max_angle>
          </horizontal>
        </scan>
        <range>
          <min>0.05</min>
          <max>29.0</max>
          <resolution>0.01</resolution>
        </range>
        <noise>
          <type>gaussian</type>
          <!-- Noise parameters based on published spec for S300 achieving
                 "+-29mm" accuracy at range < 3m (~0.01 of the range) at
                 1 sigma. -->
          <mean>0.0</mean>
          <stddev>0.01</stddev>
        </noise>
      </ray>
      <plugin filename="libgazebo_ros_gpu_laser.so" name="gazebo_ros_back_laser_link_controller">
        <!-- no tf_prefix, plugin always uses a tf_prefix (if none is set it uses robotNamespace) -->
        <frameName>/back_laser_link</frameName>
        <topicName>b_scan</topicName>
      </plugin>
    </sensor>
  </gazebo>
  <!-- Ultrasound sensors -->
  <joint name="us_1_joint" type="fixed">
    <!-- right ultrasound -->
    <parent link="base_link"/>
    <child link="us_1_frame"/>
    <origin rpy="0 0 0" xyz="0.45 -0.12 0.16 "/>
  </joint>
  <link name="us_1_frame"/>
  <joint name="us_2_joint" type="fixed">
    <!-- left ultrasound -->
    <parent link="base_link"/>
    <child link="us_2_frame"/>
    <origin rpy="0 0 0" xyz="0.45 0.12 0.16 "/>
  </joint>
  <link name="us_2_frame"/>
  <joint name="left_wheel_joint" type="continuous">
    <origin rpy="0 0 0" xyz="0.0 0.222604 0.0625"/>
    <parent link="base_link"/>
    <child link="left_wheel_link"/>
    <axis xyz="0 1 0"/>
    <limit effort="200" velocity="20.0"/>
  </joint>
  <link name="left_wheel_link">
    <inertial>
      <mass value="2"/>
      <origin rpy="1.57079632679 0 0" xyz="0 0 0"/>
      <inertia ixx="0.00212379081715" ixy="0.0" ixz="0.0" iyy="0.00212379081715" iyz="0.0" izz="0.00390625"/>
    </inertial>
    <visual>
      <origin rpy="0 0 0" xyz="0 0 0"/>
      <geometry>
        <mesh filename="package://lxfr_description/meshes/wheel.stl"/>
      </geometry>
      <material name="dark_grey">
        <color rgba="0.3 0.3 0.3 1"/>
      </material>
    </visual>
    <collision>
      <origin rpy="0 0 0" xyz="0 0 0"/>
      <geometry>
        <mesh filename="package://lxfr_description/meshes/wheel.stl"/>
      </geometry>
      <friction>
        <ode>
          <mu>2</mu>
          <mu2>2</mu2>
        </ode>
      </friction>
    </collision>
  </link>
  <gazebo reference="left_wheel_link">
    <material>Gazebo/DarkGrey</material>
  </gazebo>
  <joint name="right_wheel_joint" type="continuous">
    <origin rpy="0 0 0" xyz="0.0 -0.222604 0.0625"/>
    <parent link="base_link"/>
    <child link="right_wheel_link"/>
    <axis xyz="0 1 0"/>
    <limit effort="200" velocity="20.0"/>
  </joint>
  <link name="right_wheel_link">
    <inertial>
      <mass value="2"/>
      <origin rpy="1.57079632679 0 0" xyz="0 0 0"/>
      <inertia ixx="0.00212379081715" ixy="0.0" ixz="0.0" iyy="0.00212379081715" iyz="0.0" izz="0.00390625"/>
    </inertial>
    <visual>
      <origin rpy="0 0 0" xyz="0 0 0"/>
      <geometry>
        <mesh filename="package://lxfr_description/meshes/wheel.stl"/>
      </geometry>
      <material name="dark_grey">
        <color rgba="0.3 0.3 0.3 1"/>
      </material>
    </visual>
    <collision>
      <origin rpy="0 0 0" xyz="0 0 0"/>
      <geometry>
        <mesh filename="package://lxfr_description/meshes/wheel.stl"/>
      </geometry>
      <friction>
        <ode>
          <mu>2</mu>
          <mu2>2</mu2>
        </ode>
      </friction>
    </collision>
  </link>
  <gazebo reference="right_wheel_link">
    <material>Gazebo/DarkGrey</material>
  </gazebo>
  <!-- caster hub -->
  <joint name="fl_caster_rotation_joint" type="continuous">
    <origin rpy="0 0 0" xyz="0.341346 0.203 0.1565"/>
    <parent link="base_link"/>
    <child link="fl_caster_rotation_link"/>
    <axis xyz="0 0 1"/>
    <dynamics damping="0.01" friction="0.1"/>
  </joint>
  <link name="fl_caster_rotation_link">
    <inertial>
      <!-- <origin xyz="0 0 -0.042500000044" rpy="${0.5 * pi} ${24 * deg_to_rad} ${1.5 * pi}" /> -->
      <origin rpy="0.418879032 0 1.57079632679 " xyz="0 0 -0.042500000044"/>
      <mass value="0.3097539019"/>
      <inertia ixx="0.0005844517978" ixy="0" ixz="0" iyy="0.00052872551237" iyz="0" izz="0.00017923555074"/>
    </inertial>
    <collision>
      <origin rpy="0 0 0" xyz="0 0 0"/>
      <geometry>
        <mesh filename="package://lxfr_description/meshes/caster_wheel_base.stl"/>
      </geometry>
      <friction>
        <ode>
          <mu>2</mu>
          <mu2>2</mu2>
        </ode>
      </friction>
    </collision>
  </link>
  <gazebo reference="fl_caster_rotation_link">
    <material>Gazebo/Grey</material>
  </gazebo>
  <!-- caster wheel -->
  <joint name="fl_caster_wheel_joint" type="continuous">
    <origin rpy="0 0 0" xyz="-0.0382 0 -0.094"/>
    <parent link="fl_caster_rotation_link"/>
    <child link="fl_caster_wheel_link"/>
    <axis xyz="0 1 0"/>
  </joint>
  <link name="fl_caster_wheel_link">
    <inertial>
      <mass value="2"/>
      <origin rpy="1.57079632679 0 0" xyz="0 0 0"/>
      <inertia ixx="0.00212379081715" ixy="0.0" ixz="0.0" iyy="0.00212379081715" iyz="0.0" izz="0.00390625"/>
    </inertial>
    <collision>
      <origin rpy="0 0 0" xyz="0 0 0"/>
      <geometry>
        <mesh filename="package://lxfr_description/meshes/wheel.stl"/>
      </geometry>
      <friction>
        <ode>
          <mu>2</mu>
          <mu2>2</mu2>
        </ode>
      </friction>
    </collision>
  </link>
  <gazebo reference="fl_caster_wheel_link">
    <material>Gazebo/DarkGrey</material>
  </gazebo>
  <!-- caster hub -->
  <joint name="fr_caster_rotation_joint" type="continuous">
    <origin rpy="0 0 0" xyz="0.341346 -0.203 0.1565"/>
    <parent link="base_link"/>
    <child link="fr_caster_rotation_link"/>
    <axis xyz="0 0 1"/>
    <dynamics damping="0.01" friction="0.1"/>
  </joint>
  <link name="fr_caster_rotation_link">
    <inertial>
      <!-- <origin xyz="0 0 -0.042500000044" rpy="${0.5 * pi} ${24 * deg_to_rad} ${1.5 * pi}" /> -->
      <origin rpy="0.418879032 0 1.57079632679 " xyz="0 0 -0.042500000044"/>
      <mass value="0.3097539019"/>
      <inertia ixx="0.0005844517978" ixy="0" ixz="0" iyy="0.00052872551237" iyz="0" izz="0.00017923555074"/>
    </inertial>
    <collision>
      <origin rpy="0 0 0" xyz="0 0 0"/>
      <geometry>
        <mesh filename="package://lxfr_description/meshes/caster_wheel_base.stl"/>
      </geometry>
      <friction>
        <ode>
          <mu>2</mu>
          <mu2>2</mu2>
        </ode>
      </friction>
    </collision>
  </link>
  <gazebo reference="fr_caster_rotation_link">
    <material>Gazebo/Grey</material>
  </gazebo>
  <!-- caster wheel -->
  <joint name="fr_caster_wheel_joint" type="continuous">
    <origin rpy="0 0 0" xyz="-0.0382 0 -0.094"/>
    <parent link="fr_caster_rotation_link"/>
    <child link="fr_caster_wheel_link"/>
    <axis xyz="0 1 0"/>
  </joint>
  <link name="fr_caster_wheel_link">
    <inertial>
      <mass value="2"/>
      <origin rpy="1.57079632679 0 0" xyz="0 0 0"/>
      <inertia ixx="0.00212379081715" ixy="0.0" ixz="0.0" iyy="0.00212379081715" iyz="0.0" izz="0.00390625"/>
    </inertial>
    <collision>
      <origin rpy="0 0 0" xyz="0 0 0"/>
      <geometry>
        <mesh filename="package://lxfr_description/meshes/wheel.stl"/>
      </geometry>
      <friction>
        <ode>
          <mu>2</mu>
          <mu2>2</mu2>
        </ode>
      </friction>
    </collision>
  </link>
  <gazebo reference="fr_caster_wheel_link">
    <material>Gazebo/DarkGrey</material>
  </gazebo>
  <!-- caster hub -->
  <joint name="bl_caster_rotation_joint" type="continuous">
    <origin rpy="0 0 0" xyz="-0.270154 0.203 0.1565"/>
    <parent link="base_link"/>
    <child link="bl_caster_rotation_link"/>
    <axis xyz="0 0 1"/>
    <dynamics damping="0.01" friction="0.1"/>
  </joint>
  <link name="bl_caster_rotation_link">
    <inertial>
      <!-- <origin xyz="0 0 -0.042500000044" rpy="${0.5 * pi} ${24 * deg_to_rad} ${1.5 * pi}" /> -->
      <origin rpy="0.418879032 0 1.57079632679 " xyz="0 0 -0.042500000044"/>
      <mass value="0.3097539019"/>
      <inertia ixx="0.0005844517978" ixy="0" ixz="0" iyy="0.00052872551237" iyz="0" izz="0.00017923555074"/>
    </inertial>
    <collision>
      <origin rpy="0 0 0" xyz="0 0 0"/>
      <geometry>
        <mesh filename="package://lxfr_description/meshes/caster_wheel_base.stl"/>
      </geometry>
      <friction>
        <ode>
          <mu>2</mu>
          <mu2>2</mu2>
        </ode>
      </friction>
    </collision>
  </link>
  <gazebo reference="bl_caster_rotation_link">
    <material>Gazebo/Grey</material>
  </gazebo>
  <!-- caster wheel -->
  <joint name="bl_caster_wheel_joint" type="continuous">
    <origin rpy="0 0 0" xyz="-0.0382 0 -0.094"/>
    <parent link="bl_caster_rotation_link"/>
    <child link="bl_caster_wheel_link"/>
    <axis xyz="0 1 0"/>
  </joint>
  <link name="bl_caster_wheel_link">
    <inertial>
      <mass value="2"/>
      <origin rpy="1.57079632679 0 0" xyz="0 0 0"/>
      <inertia ixx="0.00212379081715" ixy="0.0" ixz="0.0" iyy="0.00212379081715" iyz="0.0" izz="0.00390625"/>
    </inertial>
    <collision>
      <origin rpy="0 0 0" xyz="0 0 0"/>
      <geometry>
        <mesh filename="package://lxfr_description/meshes/wheel.stl"/>
      </geometry>
      <friction>
        <ode>
          <mu>2</mu>
          <mu2>2</mu2>
        </ode>
      </friction>
    </collision>
  </link>
  <gazebo reference="bl_caster_wheel_link">
    <material>Gazebo/DarkGrey</material>
  </gazebo>
  <!-- caster hub -->
  <joint name="br_caster_rotation_joint" type="continuous">
    <origin rpy="0 0 0" xyz="-0.270154 -0.203 0.1565"/>
    <parent link="base_link"/>
    <child link="br_caster_rotation_link"/>
    <axis xyz="0 0 1"/>
    <dynamics damping="0.01" friction="0.1"/>
  </joint>
  <link name="br_caster_rotation_link">
    <inertial>
      <!-- <origin xyz="0 0 -0.042500000044" rpy="${0.5 * pi} ${24 * deg_to_rad} ${1.5 * pi}" /> -->
      <origin rpy="0.418879032 0 1.57079632679 " xyz="0 0 -0.042500000044"/>
      <mass value="0.3097539019"/>
      <inertia ixx="0.0005844517978" ixy="0" ixz="0" iyy="0.00052872551237" iyz="0" izz="0.00017923555074"/>
    </inertial>
    <collision>
      <origin rpy="0 0 0" xyz="0 0 0"/>
      <geometry>
        <mesh filename="package://lxfr_description/meshes/caster_wheel_base.stl"/>
      </geometry>
      <friction>
        <ode>
          <mu>2</mu>
          <mu2>2</mu2>
        </ode>
      </friction>
    </collision>
  </link>
  <gazebo reference="br_caster_rotation_link">
    <material>Gazebo/Grey</material>
  </gazebo>
  <!-- caster wheel -->
  <joint name="br_caster_wheel_joint" type="continuous">
    <origin rpy="0 0 0" xyz="-0.0382 0 -0.094"/>
    <parent link="br_caster_rotation_link"/>
    <child link="br_caster_wheel_link"/>
    <axis xyz="0 1 0"/>
  </joint>
  <link name="br_caster_wheel_link">
    <inertial>
      <mass value="2"/>
      <origin rpy="1.57079632679 0 0" xyz="0 0 0"/>
      <inertia ixx="0.00212379081715" ixy="0.0" ixz="0.0" iyy="0.00212379081715" iyz="0.0" izz="0.00390625"/>
    </inertial>
    <collision>
      <origin rpy="0 0 0" xyz="0 0 0"/>
      <geometry>
        <mesh filename="package://lxfr_description/meshes/wheel.stl"/>
      </geometry>
      <friction>
        <ode>
          <mu>2</mu>
          <mu2>2</mu2>
        </ode>
      </friction>
    </collision>
  </link>
  <gazebo reference="br_caster_wheel_link">
    <material>Gazebo/DarkGrey</material>
  </gazebo>
  <joint name="base_link_surface_joint" type="fixed">
    <origin rpy="0 0 0" xyz="0.037646 0 0.352"/>
    <parent link="base_link"/>
    <child link="surface"/>
    <axis xyz="0 0 1"/>
  </joint>
  <link name="surface"/>
  <transmission name="left_wheel_trans">
    <type>transmission_interface/SimpleTransmission</type>
    <joint name="left_wheel_joint">
      <hardwareInterface>hardware_interface/VelocityJointInterface</hardwareInterface>
    </joint>
    <actuator name="left_wheel_motor">
      <hardwareInterface>hardware_interface/VelocityJointInterface</hardwareInterface>
      <mechanicalReduction>1</mechanicalReduction>
    </actuator>
  </transmission>
  <transmission name="right_wheel_trans">
    <type>transmission_interface/SimpleTransmission</type>
    <joint name="right_wheel_joint">
      <hardwareInterface>hardware_interface/VelocityJointInterface</hardwareInterface>
    </joint>
    <actuator name="right_wheel_motor">
      <hardwareInterface>hardware_interface/VelocityJointInterface</hardwareInterface>
      <mechanicalReduction>1</mechanicalReduction>
    </actuator>
  </transmission>
  <!-- disabled, because it doesn't make a difference in Gazebo: -->
  <!-- <xacro:set_all_wheel_frictions prefix="${prefix}"/> -->
  <gazebo>
    <plugin filename="libgazebo_ros_p3d.so" name="p3d_base_controller">
      <alwaysOn>true</alwaysOn>
      <updateRate>50.0</updateRate>
      <bodyName>base_footprint</bodyName>
      <topicName>base_pose_ground_truth</topicName>
      <gaussianNoise>0.01</gaussianNoise>
      <frameName>map</frameName>
      <xyzOffsets>0 0 0</xyzOffsets>
      <rpyOffsets>0 0 0</rpyOffsets>
    </plugin>
  </gazebo>
  <!-- Cameras -->
  <!-- TODO: bottom camera?? -->
  <!-- <link name="camera_link">
      <collision>
        <origin xyz="0 0 0" rpy="0 0 0"/>
        <geometry>
          <box size="0.1 0.1 0.1"/>
        </geometry>
      </collision>
      <visual>
        <origin xyz="0 0 0" rpy="0 0 0"/>
        <geometry>
          <mesh filename="package://lxfr_description/meshes/realsense.dae" />
        </geometry>
      </visual>
      <inertial>
        <mass value="1e-5" />
        <origin xyz="0 0 0" rpy="0 0 0"/>
        <inertia ixx="1e-6" ixy="0" ixz="0" iyy="1e-6" iyz="0" izz="1e-6" />
      </inertial>
    </link>

    <joint name="camera_joint" type="fixed">
      <axis xyz="0 1 0" />
      <origin xyz="0.42 0 0.27" rpy="0 0.2 0"/>
      <parent link="${prefix}base_link"/>
      <child link="camera_link"/>
    </joint>

    <joint name="camera_optical_joint" type="fixed">
      <origin xyz="0 0 0" rpy="-1.5708 0 -1.5708"/>
      <parent link="camera_link"/>
      <child link="camera_link_optical"/>
    </joint>

    <link name="camera_link_optical">
    </link> -->
  <link name="front_camera_link">
    <collision>
      <origin rpy="0 0 0" xyz="0 0 0"/>
      <geometry>
        <box size="0.1 0.1 0.1"/>
      </geometry>
    </collision>
    <visual>
      <origin rpy="0 0 0" xyz="0 0 0"/>
      <geometry>
        <mesh filename="package://lxfr_description/meshes/realsense.dae"/>
      </geometry>
    </visual>
    <inertial>
      <mass value="1e-5"/>
      <origin rpy="0 0 0" xyz="0 0 0"/>
      <inertia ixx="1e-6" ixy="0" ixz="0" iyy="1e-6" iyz="0" izz="1e-6"/>
    </inertial>
  </link>
  <joint name="front_camera_joint" type="fixed">
    <axis xyz="0 1 0"/>
    <!-- <origin xyz="0.29661 0 0.54" rpy="2.4433 0 1.5708" /> -->
    <origin rpy="0 0.523598775598 0" xyz="0.27 0 0.535"/>
    <parent link="base_link"/>
    <child link="front_camera_link"/>
  </joint>
  <joint name="front_camera_optical_joint" type="fixed">
    <origin rpy="-1.57079632679 0 -1.57079632679" xyz="0 0 0"/>
    <parent link="front_camera_link"/>
    <child link="front_camera_link_optical"/>
  </joint>
  <link name="front_camera_link_optical">
    </link>
  <gazebo reference="{id}_camera_link">
    <sensor name="camera" type="depth">
      <plugin filename="libgazebo_ros_openni_kinect.so" name="kinect_camera_controller">
        <cameraName>front_camera</cameraName>
        <alwaysOn>true</alwaysOn>
        <updateRate>10</updateRate>
        <imageTopicName>rgb/image_raw</imageTopicName>
        <depthImageTopicName>depth/image_raw</depthImageTopicName>
        <pointCloudTopicName>depth/points</pointCloudTopicName>
        <cameraInfoTopicName>rgb/camera_info</cameraInfoTopicName>
        <depthImageCameraInfoTopicName>depth/camera_info</depthImageCameraInfoTopicName>
        <frameName>{id}_camera_link_optical</frameName>
        <baseline>0.1</baseline>
        <distortion_k1>0.0</distortion_k1>
        <distortion_k2>0.0</distortion_k2>
        <distortion_k3>0.0</distortion_k3>
        <distortion_t1>0.0</distortion_t1>
        <distortion_t2>0.0</distortion_t2>
        <pointCloudCutoff>0.4</pointCloudCutoff>
      </plugin>
    </sensor>
  </gazebo>
  <link name="back_camera_link">
    <collision>
      <origin rpy="0 0 0" xyz="0 0 0"/>
      <geometry>
        <box size="0.1 0.1 0.1"/>
      </geometry>
    </collision>
    <visual>
      <origin rpy="0 0 0" xyz="0 0 0"/>
      <geometry>
        <mesh filename="package://lxfr_description/meshes/realsense.dae"/>
      </geometry>
    </visual>
    <inertial>
      <mass value="1e-5"/>
      <origin rpy="0 0 0" xyz="0 0 0"/>
      <inertia ixx="1e-6" ixy="0" ixz="0" iyy="1e-6" iyz="0" izz="1e-6"/>
    </inertial>
  </link>
  <joint name="back_camera_link" type="fixed">
    <axis xyz="0 1 0"/>
    <!-- <origin xyz="-0.26804 0 0.54" rpy="2.4433 0 -1.5708" /> -->
    <origin rpy="0 0.523598775598 3.14159265359" xyz="-0.25 0 0.535"/>
    <parent link="base_link"/>
    <child link="back_camera_link"/>
  </joint>
  <joint name="back_camera_optical_joint" type="fixed">
    <origin rpy="-1.57079632679 0 -1.57079632679" xyz="0 0 0"/>
    <parent link="back_camera_link"/>
    <child link="back_camera_link_optical"/>
  </joint>
  <link name="back_camera_link_optical">
    </link>
  <gazebo reference="{id}_camera_link">
    <sensor name="camera" type="depth">
      <plugin filename="libgazebo_ros_openni_kinect.so" name="kinect_camera_controller">
        <cameraName>front_camera</cameraName>
        <alwaysOn>true</alwaysOn>
        <updateRate>10</updateRate>
        <imageTopicName>rgb/image_raw</imageTopicName>
        <depthImageTopicName>depth/image_raw</depthImageTopicName>
        <pointCloudTopicName>depth/points</pointCloudTopicName>
        <cameraInfoTopicName>rgb/camera_info</cameraInfoTopicName>
        <depthImageCameraInfoTopicName>depth/camera_info</depthImageCameraInfoTopicName>
        <frameName>{id}_camera_link_optical</frameName>
        <baseline>0.1</baseline>
        <distortion_k1>0.0</distortion_k1>
        <distortion_k2>0.0</distortion_k2>
        <distortion_k3>0.0</distortion_k3>
        <distortion_t1>0.0</distortion_t1>
        <distortion_t2>0.0</distortion_t2>
        <pointCloudCutoff>0.4</pointCloudCutoff>
      </plugin>
    </sensor>
  </gazebo>
  <!-- joint: Mobile base to UR5e -->
  <!-- TODO: replace with fixed joint between ur5e and mobile base here -->
  <!-- Done. -->
  <!-- <link name="world" />
    <joint name="world_joint" type="fixed">
      <parent link="world" />
      <child link = "$(arg tf_prefix)base_link_ur5e" />
      <origin xyz="0.0 0.0 0.5" rpy="0.0 0.0 0.0" />
    </joint> -->
  <joint name="lxfr_to_ur5e" type="fixed">
    <parent link="base_link"/>
    <child link="base_link_ur5e"/>
    <origin rpy="0.0 0.0 -1.5707963" xyz="0.224311 0 0.6"/>
  </joint>
  <!-- Link to Gazebo library -->
  <!-- Gazebo Ros Control plugin -->
  <gazebo>
    <plugin filename="libgazebo_ros_control.so" name="gazebo_ros_control">
      <!-- <robotNamespace>$(arg robot_namespace)</robotNamespace> -->
      <!--will be global namespace when not specified -->
      <controlPeriod>0.001</controlPeriod>
      <legacyModeNS>true</legacyModeNS>
      <robotParam>robot_description</robotParam>
      <!--<filterJointsParam>${joint_names}</filterJointsParam>-->
    </plugin>
  </gazebo>
</robot>

